2020-07-31 14:35:56,617 INFO: Microblog startup [in /Users/aleksandar-h/Development/GitHub/blog/app/__init__.py:59]
2020-08-04 16:05:21,683 INFO: Microblog startup [in /Users/aleksandar-h/Development/GitHub/blog/app/__init__.py:80]
2020-08-05 09:50:24,747 INFO: Microblog startup [in /Users/aleksandar-h/Development/GitHub/blog/app/__init__.py:80]
2020-08-05 09:50:30,417 ERROR: Exception on / [GET] [in /Users/aleksandar-h/Development/GitHub/blog/venv/lib/python3.8/site-packages/flask/app.py:1891]
Traceback (most recent call last):
  File "/Users/aleksandar-h/Development/GitHub/blog/venv/lib/python3.8/site-packages/flask/app.py", line 2447, in wsgi_app
    response = self.full_dispatch_request()
  File "/Users/aleksandar-h/Development/GitHub/blog/venv/lib/python3.8/site-packages/flask/app.py", line 1952, in full_dispatch_request
    rv = self.handle_user_exception(e)
  File "/Users/aleksandar-h/Development/GitHub/blog/venv/lib/python3.8/site-packages/flask/app.py", line 1821, in handle_user_exception
    reraise(exc_type, exc_value, tb)
  File "/Users/aleksandar-h/Development/GitHub/blog/venv/lib/python3.8/site-packages/flask/_compat.py", line 39, in reraise
    raise value
  File "/Users/aleksandar-h/Development/GitHub/blog/venv/lib/python3.8/site-packages/flask/app.py", line 1948, in full_dispatch_request
    rv = self.preprocess_request()
  File "/Users/aleksandar-h/Development/GitHub/blog/venv/lib/python3.8/site-packages/flask/app.py", line 2242, in preprocess_request
    rv = func()
  File "/Users/aleksandar-h/Development/GitHub/blog/app/main/routes.py", line 28, in before_request
    g.locale = str(get_locale())
  File "/Users/aleksandar-h/Development/GitHub/blog/venv/lib/python3.8/site-packages/flask_babel/__init__.py", line 251, in get_locale
    rv = babel.locale_selector_func()
  File "/Users/aleksandar-h/Development/GitHub/blog/app/__init__.py", line 86, in get_locale
    return request.accept_languages.best_match(app.config["LANGUAGES"])
NameError: name 'app' is not defined
2020-08-05 09:51:26,805 INFO: Microblog startup [in /Users/aleksandar-h/Development/GitHub/blog/app/__init__.py:80]
2020-08-05 09:51:27,972 ERROR: Exception on / [GET] [in /Users/aleksandar-h/Development/GitHub/blog/venv/lib/python3.8/site-packages/flask/app.py:1891]
Traceback (most recent call last):
  File "/Users/aleksandar-h/Development/GitHub/blog/venv/lib/python3.8/site-packages/flask/app.py", line 2447, in wsgi_app
    response = self.full_dispatch_request()
  File "/Users/aleksandar-h/Development/GitHub/blog/venv/lib/python3.8/site-packages/flask/app.py", line 1952, in full_dispatch_request
    rv = self.handle_user_exception(e)
  File "/Users/aleksandar-h/Development/GitHub/blog/venv/lib/python3.8/site-packages/flask/app.py", line 1821, in handle_user_exception
    reraise(exc_type, exc_value, tb)
  File "/Users/aleksandar-h/Development/GitHub/blog/venv/lib/python3.8/site-packages/flask/_compat.py", line 39, in reraise
    raise value
  File "/Users/aleksandar-h/Development/GitHub/blog/venv/lib/python3.8/site-packages/flask/app.py", line 1948, in full_dispatch_request
    rv = self.preprocess_request()
  File "/Users/aleksandar-h/Development/GitHub/blog/venv/lib/python3.8/site-packages/flask/app.py", line 2242, in preprocess_request
    rv = func()
  File "/Users/aleksandar-h/Development/GitHub/blog/app/main/routes.py", line 28, in before_request
    g.locale = str(get_locale())
  File "/Users/aleksandar-h/Development/GitHub/blog/venv/lib/python3.8/site-packages/flask_babel/__init__.py", line 251, in get_locale
    rv = babel.locale_selector_func()
  File "/Users/aleksandar-h/Development/GitHub/blog/app/__init__.py", line 86, in get_locale
    return request.accept_languages.best_match(current_app.config["LANGUAGES"])
NameError: name 'current_app' is not defined
2020-08-05 09:52:03,589 INFO: Microblog startup [in /Users/aleksandar-h/Development/GitHub/blog/app/__init__.py:80]
2020-08-05 09:52:04,771 ERROR: Exception on / [GET] [in /Users/aleksandar-h/Development/GitHub/blog/venv/lib/python3.8/site-packages/flask/app.py:1891]
Traceback (most recent call last):
  File "/Users/aleksandar-h/Development/GitHub/blog/venv/lib/python3.8/site-packages/flask/app.py", line 2447, in wsgi_app
    response = self.full_dispatch_request()
  File "/Users/aleksandar-h/Development/GitHub/blog/venv/lib/python3.8/site-packages/flask/app.py", line 1952, in full_dispatch_request
    rv = self.handle_user_exception(e)
  File "/Users/aleksandar-h/Development/GitHub/blog/venv/lib/python3.8/site-packages/flask/app.py", line 1821, in handle_user_exception
    reraise(exc_type, exc_value, tb)
  File "/Users/aleksandar-h/Development/GitHub/blog/venv/lib/python3.8/site-packages/flask/_compat.py", line 39, in reraise
    raise value
  File "/Users/aleksandar-h/Development/GitHub/blog/venv/lib/python3.8/site-packages/flask/app.py", line 1950, in full_dispatch_request
    rv = self.dispatch_request()
  File "/Users/aleksandar-h/Development/GitHub/blog/venv/lib/python3.8/site-packages/flask/app.py", line 1936, in dispatch_request
    return self.view_functions[rule.endpoint](**req.view_args)
  File "/Users/aleksandar-h/Development/GitHub/blog/venv/lib/python3.8/site-packages/flask_login/utils.py", line 271, in decorated_view
    return current_app.login_manager.unauthorized()
  File "/Users/aleksandar-h/Development/GitHub/blog/venv/lib/python3.8/site-packages/flask_login/login_manager.py", line 174, in unauthorized
    redirect_url = make_login_url(login_view, next_url=request.url)
  File "/Users/aleksandar-h/Development/GitHub/blog/venv/lib/python3.8/site-packages/flask_login/utils.py", line 120, in login_url
    base = expand_login_view(login_view)
  File "/Users/aleksandar-h/Development/GitHub/blog/venv/lib/python3.8/site-packages/flask_login/utils.py", line 97, in expand_login_view
    return url_for(login_view)
  File "/Users/aleksandar-h/Development/GitHub/blog/venv/lib/python3.8/site-packages/flask/helpers.py", line 370, in url_for
    return appctx.app.handle_url_build_error(error, endpoint, values)
  File "/Users/aleksandar-h/Development/GitHub/blog/venv/lib/python3.8/site-packages/flask/app.py", line 2216, in handle_url_build_error
    reraise(exc_type, exc_value, tb)
  File "/Users/aleksandar-h/Development/GitHub/blog/venv/lib/python3.8/site-packages/flask/_compat.py", line 39, in reraise
    raise value
  File "/Users/aleksandar-h/Development/GitHub/blog/venv/lib/python3.8/site-packages/flask/helpers.py", line 357, in url_for
    rv = url_adapter.build(
  File "/Users/aleksandar-h/Development/GitHub/blog/venv/lib/python3.8/site-packages/werkzeug/routing.py", line 2179, in build
    raise BuildError(endpoint, values, method, self)
werkzeug.routing.BuildError: Could not build url for endpoint 'login'. Did you mean 'auth.login' instead?
2020-08-05 09:58:23,853 INFO: Microblog startup [in /Users/aleksandar-h/Development/GitHub/blog/app/__init__.py:80]
